function probarExcepcion(){
    try{
        return a + b;
    }catch(error){
        alert("Este es el error");
    }
}